Could not import runpy module
Traceback (most recent call last):
  File "/home/gridsan/wfli/.conda/envs/pmp/lib/python3.8/runpy.py", line 185, in _run_module_as_main
  File "/home/gridsan/wfli/.conda/envs/pmp/lib/python3.8/runpy.py", line 144, in _get_module_details
  File "/home/gridsan/wfli/.conda/envs/pmp/lib/python3.8/runpy.py", line 155, in _get_module_details
  File "<frozen importlib._bootstrap_external>", line 980, in get_code
  File "<frozen importlib._bootstrap_external>", line 1037, in get_data
BrokenPipeError: [Errno 108] Cannot send after transport endpoint shutdown: '/home/gridsan/wfli/.conda/envs/pmp/lib/python3.8/site-packages/mpi4py/__main__.py'
Traceback (most recent call last):
  File "/home/gridsan/wfli/.conda/envs/pmp/lib/python3.8/runpy.py", line 185, in _run_module_as_main
  File "/home/gridsan/wfli/.conda/envs/pmp/lib/python3.8/runpy.py", line 144, in _get_module_details
  File "/home/gridsan/wfli/.conda/envs/pmp/lib/python3.8/runpy.py", line 155, in _get_module_details
  File "<frozen importlib._bootstrap_external>", line 980, in get_code
  File "<frozen importlib._bootstrap_external>", line 1037, in get_data
BrokenPipeError: [Errno 108] Cannot send after transport endpoint shutdown: '/home/gridsan/wfli/.conda/envs/pmp/lib/python3.8/site-packages/mpi4py/__main__.py'
Traceback (most recent call last):
  File "/home/gridsan/wfli/.conda/envs/pmp/lib/python3.8/runpy.py", line 185, in _run_module_as_main
  File "/home/gridsan/wfli/.conda/envs/pmp/lib/python3.8/runpy.py", line 144, in _get_module_details
  File "/home/gridsan/wfli/.conda/envs/pmp/lib/python3.8/runpy.py", line 155, in _get_module_details
  File "<frozen importlib._bootstrap_external>", line 980, in get_code
  File "<frozen importlib._bootstrap_external>", line 1037, in get_data
BrokenPipeError: [Errno 108] Cannot send after transport endpoint shutdown: '/home/gridsan/wfli/.conda/envs/pmp/lib/python3.8/site-packages/mpi4py/__main__.py'
Traceback (most recent call last):
  File "/home/gridsan/wfli/.conda/envs/pmp/lib/python3.8/runpy.py", line 194, in _run_module_as_main
  File "/home/gridsan/wfli/.conda/envs/pmp/lib/python3.8/runpy.py", line 87, in _run_code
  File "/home/gridsan/wfli/.conda/envs/pmp/lib/python3.8/site-packages/mpi4py/__main__.py", line 7, in <module>
  File "/home/gridsan/wfli/.conda/envs/pmp/lib/python3.8/site-packages/mpi4py/run.py", line 196, in main
  File "/home/gridsan/wfli/.conda/envs/pmp/lib/python3.8/site-packages/mpi4py/run.py", line 47, in run_command_line
  File "/home/gridsan/wfli/.conda/envs/pmp/lib/python3.8/runpy.py", line 264, in run_path
  File "/home/gridsan/wfli/.conda/envs/pmp/lib/python3.8/runpy.py", line 234, in _get_code_from_file
BrokenPipeError: [Errno 108] Cannot send after transport endpoint shutdown: '/home/gridsan/wfli/18.369_final_project/adjoint_method/test_some_gradients.py'
Traceback (most recent call last):
  File "/home/gridsan/wfli/.conda/envs/pmp/lib/python3.8/runpy.py", line 194, in _run_module_as_main
  File "/home/gridsan/wfli/.conda/envs/pmp/lib/python3.8/runpy.py", line 87, in _run_code
  File "/home/gridsan/wfli/.conda/envs/pmp/lib/python3.8/site-packages/mpi4py/__main__.py", line 7, in <module>
  File "/home/gridsan/wfli/.conda/envs/pmp/lib/python3.8/site-packages/mpi4py/run.py", line 196, in main
  File "/home/gridsan/wfli/.conda/envs/pmp/lib/python3.8/site-packages/mpi4py/run.py", line 47, in run_command_line
  File "/home/gridsan/wfli/.conda/envs/pmp/lib/python3.8/runpy.py", line 264, in run_path
  File "/home/gridsan/wfli/.conda/envs/pmp/lib/python3.8/runpy.py", line 234, in _get_code_from_file
BrokenPipeError: [Errno 108] Cannot send after transport endpoint shutdown: '/home/gridsan/wfli/18.369_final_project/adjoint_method/test_some_gradients.py'
Traceback (most recent call last):
  File "/home/gridsan/wfli/.conda/envs/pmp/lib/python3.8/runpy.py", line 185, in _run_module_as_main
  File "/home/gridsan/wfli/.conda/envs/pmp/lib/python3.8/runpy.py", line 144, in _get_module_details
  File "/home/gridsan/wfli/.conda/envs/pmp/lib/python3.8/runpy.py", line 130, in _get_module_details
  File "/home/gridsan/wfli/.conda/envs/pmp/lib/python3.8/importlib/util.py", line 103, in find_spec
  File "<frozen importlib._bootstrap>", line 914, in _find_spec
  File "<frozen importlib._bootstrap_external>", line 1407, in find_spec
  File "<frozen importlib._bootstrap_external>", line 1379, in _get_spec
  File "<frozen importlib._bootstrap_external>", line 1510, in find_spec
  File "<frozen importlib._bootstrap_external>", line 1553, in _fill_cache
BrokenPipeError: [Errno 108] Cannot send after transport endpoint shutdown: '/home/gridsan/wfli/.conda/envs/pmp/lib/python3.8/site-packages/mpi4py'
Traceback (most recent call last):
  File "/home/gridsan/wfli/.conda/envs/pmp/lib/python3.8/runpy.py", line 194, in _run_module_as_main
  File "/home/gridsan/wfli/.conda/envs/pmp/lib/python3.8/runpy.py", line 87, in _run_code
  File "/home/gridsan/wfli/.conda/envs/pmp/lib/python3.8/site-packages/mpi4py/__main__.py", line 4, in <module>
  File "<frozen importlib._bootstrap>", line 991, in _find_and_load
  File "<frozen importlib._bootstrap>", line 975, in _find_and_load_unlocked
  File "<frozen importlib._bootstrap>", line 671, in _load_unlocked
  File "<frozen importlib._bootstrap_external>", line 844, in exec_module
  File "<frozen importlib._bootstrap_external>", line 980, in get_code
  File "<frozen importlib._bootstrap_external>", line 1037, in get_data
BrokenPipeError: [Errno 108] Cannot send after transport endpoint shutdown: '/home/gridsan/wfli/.conda/envs/pmp/lib/python3.8/site-packages/mpi4py/run.py'
Traceback (most recent call last):
  File "/home/gridsan/wfli/.conda/envs/pmp/lib/python3.8/runpy.py", line 194, in _run_module_as_main
  File "/home/gridsan/wfli/.conda/envs/pmp/lib/python3.8/runpy.py", line 87, in _run_code
  File "/home/gridsan/wfli/.conda/envs/pmp/lib/python3.8/site-packages/mpi4py/__main__.py", line 4, in <module>
  File "<frozen importlib._bootstrap>", line 991, in _find_and_load
  File "<frozen importlib._bootstrap>", line 975, in _find_and_load_unlocked
  File "<frozen importlib._bootstrap>", line 671, in _load_unlocked
  File "<frozen importlib._bootstrap_external>", line 844, in exec_module
  File "<frozen importlib._bootstrap_external>", line 980, in get_code
  File "<frozen importlib._bootstrap_external>", line 1037, in get_data
BrokenPipeError: [Errno 108] Cannot send after transport endpoint shutdown: '/home/gridsan/wfli/.conda/envs/pmp/lib/python3.8/site-packages/mpi4py/run.py'
Traceback (most recent call last):
  File "/home/gridsan/wfli/.conda/envs/pmp/lib/python3.8/runpy.py", line 185, in _run_module_as_main
  File "/home/gridsan/wfli/.conda/envs/pmp/lib/python3.8/runpy.py", line 144, in _get_module_details
  File "/home/gridsan/wfli/.conda/envs/pmp/lib/python3.8/runpy.py", line 111, in _get_module_details
  File "<frozen importlib._bootstrap>", line 991, in _find_and_load
  File "<frozen importlib._bootstrap>", line 975, in _find_and_load_unlocked
  File "<frozen importlib._bootstrap>", line 671, in _load_unlocked
  File "<frozen importlib._bootstrap_external>", line 844, in exec_module
  File "<frozen importlib._bootstrap_external>", line 980, in get_code
  File "<frozen importlib._bootstrap_external>", line 1037, in get_data
BrokenPipeError: [Errno 108] Cannot send after transport endpoint shutdown: '/home/gridsan/wfli/.conda/envs/pmp/lib/python3.8/site-packages/mpi4py/__init__.py'
Traceback (most recent call last):
  File "/home/gridsan/wfli/.conda/envs/pmp/lib/python3.8/runpy.py", line 194, in _run_module_as_main
  File "/home/gridsan/wfli/.conda/envs/pmp/lib/python3.8/runpy.py", line 87, in _run_code
  File "/home/gridsan/wfli/.conda/envs/pmp/lib/python3.8/site-packages/mpi4py/__main__.py", line 4, in <module>
  File "/home/gridsan/wfli/.conda/envs/pmp/lib/python3.8/site-packages/mpi4py/run.py", line 9, in <module>
  File "<frozen importlib._bootstrap>", line 991, in _find_and_load
  File "<frozen importlib._bootstrap>", line 975, in _find_and_load_unlocked
  File "<frozen importlib._bootstrap>", line 671, in _load_unlocked
  File "<frozen importlib._bootstrap_external>", line 844, in exec_module
  File "<frozen importlib._bootstrap_external>", line 980, in get_code
  File "<frozen importlib._bootstrap_external>", line 1037, in get_data
BrokenPipeError: [Errno 108] Cannot send after transport endpoint shutdown: '/home/gridsan/wfli/.conda/envs/pmp/lib/python3.8/__future__.py'
Traceback (most recent call last):
  File "/home/gridsan/wfli/.conda/envs/pmp/lib/python3.8/runpy.py", line 19, in <module>
  File "/home/gridsan/wfli/.conda/envs/pmp/lib/python3.8/pkgutil.py", line 137, in <module>
  File "/home/gridsan/wfli/.conda/envs/pmp/lib/python3.8/functools.py", line 808, in singledispatch
  File "/home/gridsan/wfli/.conda/envs/pmp/lib/python3.8/weakref.py", line 22, in <module>
  File "<frozen importlib._bootstrap>", line 991, in _find_and_load
  File "<frozen importlib._bootstrap>", line 975, in _find_and_load_unlocked
  File "<frozen importlib._bootstrap>", line 671, in _load_unlocked
  File "<frozen importlib._bootstrap_external>", line 844, in exec_module
  File "<frozen importlib._bootstrap_external>", line 980, in get_code
  File "<frozen importlib._bootstrap_external>", line 1037, in get_data
BrokenPipeError: [Errno 108] Cannot send after transport endpoint shutdown: '/home/gridsan/wfli/.conda/envs/pmp/lib/python3.8/_weakrefset.py'
Traceback (most recent call last):
  File "/home/gridsan/wfli/.conda/envs/pmp/lib/python3.8/runpy.py", line 194, in _run_module_as_main
  File "/home/gridsan/wfli/.conda/envs/pmp/lib/python3.8/runpy.py", line 87, in _run_code
  File "/home/gridsan/wfli/.conda/envs/pmp/lib/python3.8/site-packages/mpi4py/__main__.py", line 4, in <module>
  File "/home/gridsan/wfli/.conda/envs/pmp/lib/python3.8/site-packages/mpi4py/run.py", line 9, in <module>
  File "<frozen importlib._bootstrap>", line 991, in _find_and_load
  File "<frozen importlib._bootstrap>", line 975, in _find_and_load_unlocked
  File "<frozen importlib._bootstrap>", line 671, in _load_unlocked
  File "<frozen importlib._bootstrap_external>", line 844, in exec_module
  File "<frozen importlib._bootstrap_external>", line 980, in get_code
  File "<frozen importlib._bootstrap_external>", line 1037, in get_data
BrokenPipeError: [Errno 108] Cannot send after transport endpoint shutdown: '/home/gridsan/wfli/.conda/envs/pmp/lib/python3.8/__future__.py'
Traceback (most recent call last):
  File "/home/gridsan/wfli/.conda/envs/pmp/lib/python3.8/runpy.py", line 194, in _run_module_as_main
  File "/home/gridsan/wfli/.conda/envs/pmp/lib/python3.8/runpy.py", line 87, in _run_code
  File "/home/gridsan/wfli/.conda/envs/pmp/lib/python3.8/site-packages/mpi4py/__main__.py", line 4, in <module>
  File "/home/gridsan/wfli/.conda/envs/pmp/lib/python3.8/site-packages/mpi4py/run.py", line 9, in <module>
  File "<frozen importlib._bootstrap>", line 991, in _find_and_load
  File "<frozen importlib._bootstrap>", line 975, in _find_and_load_unlocked
  File "<frozen importlib._bootstrap>", line 671, in _load_unlocked
  File "<frozen importlib._bootstrap_external>", line 844, in exec_module
  File "<frozen importlib._bootstrap_external>", line 980, in get_code
  File "<frozen importlib._bootstrap_external>", line 1037, in get_data
BrokenPipeError: [Errno 108] Cannot send after transport endpoint shutdown: '/home/gridsan/wfli/.conda/envs/pmp/lib/python3.8/__future__.py'
Traceback (most recent call last):
  File "/home/gridsan/wfli/.conda/envs/pmp/lib/python3.8/runpy.py", line 194, in _run_module_as_main
  File "/home/gridsan/wfli/.conda/envs/pmp/lib/python3.8/runpy.py", line 87, in _run_code
  File "/home/gridsan/wfli/.conda/envs/pmp/lib/python3.8/site-packages/mpi4py/__main__.py", line 4, in <module>
  File "<frozen importlib._bootstrap>", line 991, in _find_and_load
  File "<frozen importlib._bootstrap>", line 971, in _find_and_load_unlocked
  File "<frozen importlib._bootstrap>", line 914, in _find_spec
  File "<frozen importlib._bootstrap_external>", line 1407, in find_spec
  File "<frozen importlib._bootstrap_external>", line 1379, in _get_spec
  File "<frozen importlib._bootstrap_external>", line 1510, in find_spec
  File "<frozen importlib._bootstrap_external>", line 1553, in _fill_cache
BrokenPipeError: [Errno 108] Cannot send after transport endpoint shutdown: '/home/gridsan/wfli/.conda/envs/pmp/lib/python3.8/site-packages/mpi4py'
Traceback (most recent call last):
  File "/home/gridsan/wfli/.conda/envs/pmp/lib/python3.8/runpy.py", line 194, in _run_module_as_main
  File "/home/gridsan/wfli/.conda/envs/pmp/lib/python3.8/runpy.py", line 87, in _run_code
  File "/home/gridsan/wfli/.conda/envs/pmp/lib/python3.8/site-packages/mpi4py/__main__.py", line 7, in <module>
  File "/home/gridsan/wfli/.conda/envs/pmp/lib/python3.8/site-packages/mpi4py/run.py", line 196, in main
  File "/home/gridsan/wfli/.conda/envs/pmp/lib/python3.8/site-packages/mpi4py/run.py", line 47, in run_command_line
  File "/home/gridsan/wfli/.conda/envs/pmp/lib/python3.8/runpy.py", line 265, in run_path
  File "/home/gridsan/wfli/.conda/envs/pmp/lib/python3.8/runpy.py", line 97, in _run_module_code
  File "/home/gridsan/wfli/.conda/envs/pmp/lib/python3.8/runpy.py", line 87, in _run_code
  File "test_some_gradients.py", line 1, in <module>
  File "/home/gridsan/wfli/18.369_final_project/adjoint_method/adjoint_2d.py", line 1, in <module>
  File "/home/gridsan/wfli/.conda/envs/pmp/lib/python3.8/site-packages/meep/__init__.py", line 13, in <module>
ImportError: libmpb.so.1: cannot open shared object file: No such file or directory
Traceback (most recent call last):
  File "/home/gridsan/wfli/.conda/envs/pmp/lib/python3.8/runpy.py", line 194, in _run_module_as_main
  File "/home/gridsan/wfli/.conda/envs/pmp/lib/python3.8/runpy.py", line 87, in _run_code
  File "/home/gridsan/wfli/.conda/envs/pmp/lib/python3.8/site-packages/mpi4py/__main__.py", line 7, in <module>
  File "/home/gridsan/wfli/.conda/envs/pmp/lib/python3.8/site-packages/mpi4py/run.py", line 196, in main
  File "/home/gridsan/wfli/.conda/envs/pmp/lib/python3.8/site-packages/mpi4py/run.py", line 47, in run_command_line
  File "/home/gridsan/wfli/.conda/envs/pmp/lib/python3.8/runpy.py", line 265, in run_path
  File "/home/gridsan/wfli/.conda/envs/pmp/lib/python3.8/runpy.py", line 97, in _run_module_code
  File "/home/gridsan/wfli/.conda/envs/pmp/lib/python3.8/runpy.py", line 87, in _run_code
  File "test_some_gradients.py", line 1, in <module>
  File "/home/gridsan/wfli/18.369_final_project/adjoint_method/adjoint_2d.py", line 1, in <module>
  File "/home/gridsan/wfli/.conda/envs/pmp/lib/python3.8/site-packages/meep/__init__.py", line 13, in <module>
ImportError: libmpb.so.1: cannot open shared object file: No such file or directory
Traceback (most recent call last):
  File "/home/gridsan/wfli/.conda/envs/pmp/lib/python3.8/runpy.py", line 194, in _run_module_as_main
  File "/home/gridsan/wfli/.conda/envs/pmp/lib/python3.8/runpy.py", line 87, in _run_code
  File "/home/gridsan/wfli/.conda/envs/pmp/lib/python3.8/site-packages/mpi4py/__main__.py", line 7, in <module>
  File "/home/gridsan/wfli/.conda/envs/pmp/lib/python3.8/site-packages/mpi4py/run.py", line 196, in main
  File "/home/gridsan/wfli/.conda/envs/pmp/lib/python3.8/site-packages/mpi4py/run.py", line 47, in run_command_line
  File "/home/gridsan/wfli/.conda/envs/pmp/lib/python3.8/runpy.py", line 265, in run_path
  File "/home/gridsan/wfli/.conda/envs/pmp/lib/python3.8/runpy.py", line 97, in _run_module_code
  File "/home/gridsan/wfli/.conda/envs/pmp/lib/python3.8/runpy.py", line 87, in _run_code
  File "test_some_gradients.py", line 1, in <module>
  File "/home/gridsan/wfli/18.369_final_project/adjoint_method/adjoint_2d.py", line 1, in <module>
  File "/home/gridsan/wfli/.conda/envs/pmp/lib/python3.8/site-packages/meep/__init__.py", line 13, in <module>
ImportError: libharminv.so.3: cannot open shared object file: No such file or directory
Traceback (most recent call last):
  File "/home/gridsan/wfli/.conda/envs/pmp/lib/python3.8/runpy.py", line 194, in _run_module_as_main
  File "/home/gridsan/wfli/.conda/envs/pmp/lib/python3.8/runpy.py", line 87, in _run_code
  File "/home/gridsan/wfli/.conda/envs/pmp/lib/python3.8/site-packages/mpi4py/__main__.py", line 7, in <module>
  File "/home/gridsan/wfli/.conda/envs/pmp/lib/python3.8/site-packages/mpi4py/run.py", line 196, in main
  File "/home/gridsan/wfli/.conda/envs/pmp/lib/python3.8/site-packages/mpi4py/run.py", line 47, in run_command_line
  File "/home/gridsan/wfli/.conda/envs/pmp/lib/python3.8/runpy.py", line 265, in run_path
  File "/home/gridsan/wfli/.conda/envs/pmp/lib/python3.8/runpy.py", line 97, in _run_module_code
  File "/home/gridsan/wfli/.conda/envs/pmp/lib/python3.8/runpy.py", line 87, in _run_code
  File "test_some_gradients.py", line 1, in <module>
  File "/home/gridsan/wfli/18.369_final_project/adjoint_method/adjoint_2d.py", line 1, in <module>
  File "/home/gridsan/wfli/.conda/envs/pmp/lib/python3.8/site-packages/meep/__init__.py", line 13, in <module>
ImportError: libharminv.so.3: cannot open shared object file: No such file or directory
Traceback (most recent call last):
  File "/home/gridsan/wfli/.conda/envs/pmp/lib/python3.8/runpy.py", line 194, in _run_module_as_main
  File "/home/gridsan/wfli/.conda/envs/pmp/lib/python3.8/runpy.py", line 87, in _run_code
  File "/home/gridsan/wfli/.conda/envs/pmp/lib/python3.8/site-packages/mpi4py/__main__.py", line 7, in <module>
  File "/home/gridsan/wfli/.conda/envs/pmp/lib/python3.8/site-packages/mpi4py/run.py", line 196, in main
  File "/home/gridsan/wfli/.conda/envs/pmp/lib/python3.8/site-packages/mpi4py/run.py", line 47, in run_command_line
  File "/home/gridsan/wfli/.conda/envs/pmp/lib/python3.8/runpy.py", line 265, in run_path
  File "/home/gridsan/wfli/.conda/envs/pmp/lib/python3.8/runpy.py", line 97, in _run_module_code
  File "/home/gridsan/wfli/.conda/envs/pmp/lib/python3.8/runpy.py", line 87, in _run_code
  File "test_some_gradients.py", line 1, in <module>
  File "/home/gridsan/wfli/18.369_final_project/adjoint_method/adjoint_2d.py", line 1, in <module>
  File "/home/gridsan/wfli/.conda/envs/pmp/lib/python3.8/site-packages/meep/__init__.py", line 13, in <module>
ImportError: libharminv.so.3: cannot open shared object file: No such file or directory
Traceback (most recent call last):
  File "/home/gridsan/wfli/.conda/envs/pmp/lib/python3.8/runpy.py", line 194, in _run_module_as_main
  File "/home/gridsan/wfli/.conda/envs/pmp/lib/python3.8/runpy.py", line 87, in _run_code
  File "/home/gridsan/wfli/.conda/envs/pmp/lib/python3.8/site-packages/mpi4py/__main__.py", line 7, in <module>
  File "/home/gridsan/wfli/.conda/envs/pmp/lib/python3.8/site-packages/mpi4py/run.py", line 196, in main
  File "/home/gridsan/wfli/.conda/envs/pmp/lib/python3.8/site-packages/mpi4py/run.py", line 47, in run_command_line
  File "/home/gridsan/wfli/.conda/envs/pmp/lib/python3.8/runpy.py", line 265, in run_path
  File "/home/gridsan/wfli/.conda/envs/pmp/lib/python3.8/runpy.py", line 97, in _run_module_code
  File "/home/gridsan/wfli/.conda/envs/pmp/lib/python3.8/runpy.py", line 87, in _run_code
  File "test_some_gradients.py", line 1, in <module>
  File "/home/gridsan/wfli/18.369_final_project/adjoint_method/adjoint_2d.py", line 1, in <module>
  File "/home/gridsan/wfli/.conda/envs/pmp/lib/python3.8/site-packages/meep/__init__.py", line 13, in <module>
ImportError: libgfortran.so.5: cannot open shared object file: No such file or directory
Traceback (most recent call last):
  File "/home/gridsan/wfli/.conda/envs/pmp/lib/python3.8/runpy.py", line 194, in _run_module_as_main
  File "/home/gridsan/wfli/.conda/envs/pmp/lib/python3.8/runpy.py", line 87, in _run_code
  File "/home/gridsan/wfli/.conda/envs/pmp/lib/python3.8/site-packages/mpi4py/__main__.py", line 7, in <module>
  File "/home/gridsan/wfli/.conda/envs/pmp/lib/python3.8/site-packages/mpi4py/run.py", line 196, in main
  File "/home/gridsan/wfli/.conda/envs/pmp/lib/python3.8/site-packages/mpi4py/run.py", line 47, in run_command_line
  File "/home/gridsan/wfli/.conda/envs/pmp/lib/python3.8/runpy.py", line 265, in run_path
  File "/home/gridsan/wfli/.conda/envs/pmp/lib/python3.8/runpy.py", line 97, in _run_module_code
  File "/home/gridsan/wfli/.conda/envs/pmp/lib/python3.8/runpy.py", line 87, in _run_code
  File "test_some_gradients.py", line 1, in <module>
  File "/home/gridsan/wfli/18.369_final_project/adjoint_method/adjoint_2d.py", line 1, in <module>
  File "/home/gridsan/wfli/.conda/envs/pmp/lib/python3.8/site-packages/meep/__init__.py", line 13, in <module>
ImportError: libgfortran.so.5: cannot open shared object file: No such file or directory
Traceback (most recent call last):
  File "/home/gridsan/wfli/.conda/envs/pmp/lib/python3.8/runpy.py", line 194, in _run_module_as_main
  File "/home/gridsan/wfli/.conda/envs/pmp/lib/python3.8/runpy.py", line 87, in _run_code
  File "/home/gridsan/wfli/.conda/envs/pmp/lib/python3.8/site-packages/mpi4py/__main__.py", line 7, in <module>
  File "/home/gridsan/wfli/.conda/envs/pmp/lib/python3.8/site-packages/mpi4py/run.py", line 196, in main
  File "/home/gridsan/wfli/.conda/envs/pmp/lib/python3.8/site-packages/mpi4py/run.py", line 47, in run_command_line
  File "/home/gridsan/wfli/.conda/envs/pmp/lib/python3.8/runpy.py", line 265, in run_path
  File "/home/gridsan/wfli/.conda/envs/pmp/lib/python3.8/runpy.py", line 97, in _run_module_code
  File "/home/gridsan/wfli/.conda/envs/pmp/lib/python3.8/runpy.py", line 87, in _run_code
  File "test_some_gradients.py", line 1, in <module>
  File "/home/gridsan/wfli/18.369_final_project/adjoint_method/adjoint_2d.py", line 1, in <module>
  File "/home/gridsan/wfli/.conda/envs/pmp/lib/python3.8/site-packages/meep/__init__.py", line 13, in <module>
ImportError: libmpb.so.1: cannot open shared object file: No such file or directory
Traceback (most recent call last):
  File "/home/gridsan/wfli/.conda/envs/pmp/lib/python3.8/runpy.py", line 194, in _run_module_as_main
  File "/home/gridsan/wfli/.conda/envs/pmp/lib/python3.8/runpy.py", line 87, in _run_code
  File "/home/gridsan/wfli/.conda/envs/pmp/lib/python3.8/site-packages/mpi4py/__main__.py", line 7, in <module>
  File "/home/gridsan/wfli/.conda/envs/pmp/lib/python3.8/site-packages/mpi4py/run.py", line 196, in main
  File "/home/gridsan/wfli/.conda/envs/pmp/lib/python3.8/site-packages/mpi4py/run.py", line 47, in run_command_line
  File "/home/gridsan/wfli/.conda/envs/pmp/lib/python3.8/runpy.py", line 265, in run_path
  File "/home/gridsan/wfli/.conda/envs/pmp/lib/python3.8/runpy.py", line 97, in _run_module_code
  File "/home/gridsan/wfli/.conda/envs/pmp/lib/python3.8/runpy.py", line 87, in _run_code
  File "test_some_gradients.py", line 1, in <module>
  File "/home/gridsan/wfli/18.369_final_project/adjoint_method/adjoint_2d.py", line 1, in <module>
  File "/home/gridsan/wfli/.conda/envs/pmp/lib/python3.8/site-packages/meep/__init__.py", line 13, in <module>
ImportError: libgfortran.so.5: cannot open shared object file: No such file or directory
Traceback (most recent call last):
  File "/home/gridsan/wfli/.conda/envs/pmp/lib/python3.8/runpy.py", line 194, in _run_module_as_main
  File "/home/gridsan/wfli/.conda/envs/pmp/lib/python3.8/runpy.py", line 87, in _run_code
  File "/home/gridsan/wfli/.conda/envs/pmp/lib/python3.8/site-packages/mpi4py/__main__.py", line 7, in <module>
  File "/home/gridsan/wfli/.conda/envs/pmp/lib/python3.8/site-packages/mpi4py/run.py", line 196, in main
  File "/home/gridsan/wfli/.conda/envs/pmp/lib/python3.8/site-packages/mpi4py/run.py", line 47, in run_command_line
  File "/home/gridsan/wfli/.conda/envs/pmp/lib/python3.8/runpy.py", line 265, in run_path
  File "/home/gridsan/wfli/.conda/envs/pmp/lib/python3.8/runpy.py", line 97, in _run_module_code
  File "/home/gridsan/wfli/.conda/envs/pmp/lib/python3.8/runpy.py", line 87, in _run_code
  File "test_some_gradients.py", line 1, in <module>
  File "/home/gridsan/wfli/18.369_final_project/adjoint_method/adjoint_2d.py", line 1, in <module>
  File "/home/gridsan/wfli/.conda/envs/pmp/lib/python3.8/site-packages/meep/__init__.py", line 13, in <module>
ImportError: libmpb.so.1: cannot open shared object file: No such file or directory
Traceback (most recent call last):
  File "/home/gridsan/wfli/.conda/envs/pmp/lib/python3.8/runpy.py", line 194, in _run_module_as_main
  File "/home/gridsan/wfli/.conda/envs/pmp/lib/python3.8/runpy.py", line 87, in _run_code
  File "/home/gridsan/wfli/.conda/envs/pmp/lib/python3.8/site-packages/mpi4py/__main__.py", line 7, in <module>
  File "/home/gridsan/wfli/.conda/envs/pmp/lib/python3.8/site-packages/mpi4py/run.py", line 196, in main
  File "/home/gridsan/wfli/.conda/envs/pmp/lib/python3.8/site-packages/mpi4py/run.py", line 47, in run_command_line
  File "/home/gridsan/wfli/.conda/envs/pmp/lib/python3.8/runpy.py", line 265, in run_path
  File "/home/gridsan/wfli/.conda/envs/pmp/lib/python3.8/runpy.py", line 97, in _run_module_code
  File "/home/gridsan/wfli/.conda/envs/pmp/lib/python3.8/runpy.py", line 87, in _run_code
  File "test_some_gradients.py", line 1, in <module>
  File "/home/gridsan/wfli/18.369_final_project/adjoint_method/adjoint_2d.py", line 1, in <module>
  File "/home/gridsan/wfli/.conda/envs/pmp/lib/python3.8/site-packages/meep/__init__.py", line 13, in <module>
ImportError: libmpicxx.so.12: cannot open shared object file: No such file or directory
Traceback (most recent call last):
  File "/home/gridsan/wfli/.conda/envs/pmp/lib/python3.8/runpy.py", line 194, in _run_module_as_main
  File "/home/gridsan/wfli/.conda/envs/pmp/lib/python3.8/runpy.py", line 87, in _run_code
  File "/home/gridsan/wfli/.conda/envs/pmp/lib/python3.8/site-packages/mpi4py/__main__.py", line 7, in <module>
  File "/home/gridsan/wfli/.conda/envs/pmp/lib/python3.8/site-packages/mpi4py/run.py", line 196, in main
  File "/home/gridsan/wfli/.conda/envs/pmp/lib/python3.8/site-packages/mpi4py/run.py", line 47, in run_command_line
  File "/home/gridsan/wfli/.conda/envs/pmp/lib/python3.8/runpy.py", line 265, in run_path
  File "/home/gridsan/wfli/.conda/envs/pmp/lib/python3.8/runpy.py", line 97, in _run_module_code
  File "/home/gridsan/wfli/.conda/envs/pmp/lib/python3.8/runpy.py", line 87, in _run_code
  File "test_some_gradients.py", line 1, in <module>
  File "/home/gridsan/wfli/18.369_final_project/adjoint_method/adjoint_2d.py", line 1, in <module>
  File "/home/gridsan/wfli/.conda/envs/pmp/lib/python3.8/site-packages/meep/__init__.py", line 13, in <module>
ImportError: libgsl.so.25: cannot open shared object file: No such file or directory
Traceback (most recent call last):
  File "/home/gridsan/wfli/.conda/envs/pmp/lib/python3.8/runpy.py", line 194, in _run_module_as_main
  File "/home/gridsan/wfli/.conda/envs/pmp/lib/python3.8/runpy.py", line 87, in _run_code
  File "/home/gridsan/wfli/.conda/envs/pmp/lib/python3.8/site-packages/mpi4py/__main__.py", line 7, in <module>
  File "/home/gridsan/wfli/.conda/envs/pmp/lib/python3.8/site-packages/mpi4py/run.py", line 196, in main
  File "/home/gridsan/wfli/.conda/envs/pmp/lib/python3.8/site-packages/mpi4py/run.py", line 47, in run_command_line
  File "/home/gridsan/wfli/.conda/envs/pmp/lib/python3.8/runpy.py", line 265, in run_path
  File "/home/gridsan/wfli/.conda/envs/pmp/lib/python3.8/runpy.py", line 97, in _run_module_code
  File "/home/gridsan/wfli/.conda/envs/pmp/lib/python3.8/runpy.py", line 87, in _run_code
  File "test_some_gradients.py", line 1, in <module>
  File "/home/gridsan/wfli/18.369_final_project/adjoint_method/adjoint_2d.py", line 1, in <module>
  File "/home/gridsan/wfli/.conda/envs/pmp/lib/python3.8/site-packages/meep/__init__.py", line 13, in <module>
ImportError: libmpb.so.1: cannot open shared object file: No such file or directory
Traceback (most recent call last):
  File "/home/gridsan/wfli/.conda/envs/pmp/lib/python3.8/runpy.py", line 194, in _run_module_as_main
  File "/home/gridsan/wfli/.conda/envs/pmp/lib/python3.8/runpy.py", line 87, in _run_code
  File "/home/gridsan/wfli/.conda/envs/pmp/lib/python3.8/site-packages/mpi4py/__main__.py", line 7, in <module>
  File "/home/gridsan/wfli/.conda/envs/pmp/lib/python3.8/site-packages/mpi4py/run.py", line 196, in main
  File "/home/gridsan/wfli/.conda/envs/pmp/lib/python3.8/site-packages/mpi4py/run.py", line 47, in run_command_line
  File "/home/gridsan/wfli/.conda/envs/pmp/lib/python3.8/runpy.py", line 265, in run_path
  File "/home/gridsan/wfli/.conda/envs/pmp/lib/python3.8/runpy.py", line 97, in _run_module_code
  File "/home/gridsan/wfli/.conda/envs/pmp/lib/python3.8/runpy.py", line 87, in _run_code
  File "test_some_gradients.py", line 1, in <module>
  File "/home/gridsan/wfli/18.369_final_project/adjoint_method/adjoint_2d.py", line 1, in <module>
  File "/home/gridsan/wfli/.conda/envs/pmp/lib/python3.8/site-packages/meep/__init__.py", line 13, in <module>
ImportError: libmpb.so.1: cannot open shared object file: No such file or directory
Traceback (most recent call last):
  File "/home/gridsan/wfli/.conda/envs/pmp/lib/python3.8/runpy.py", line 194, in _run_module_as_main
  File "/home/gridsan/wfli/.conda/envs/pmp/lib/python3.8/runpy.py", line 87, in _run_code
  File "/home/gridsan/wfli/.conda/envs/pmp/lib/python3.8/site-packages/mpi4py/__main__.py", line 7, in <module>
  File "/home/gridsan/wfli/.conda/envs/pmp/lib/python3.8/site-packages/mpi4py/run.py", line 196, in main
  File "/home/gridsan/wfli/.conda/envs/pmp/lib/python3.8/site-packages/mpi4py/run.py", line 47, in run_command_line
  File "/home/gridsan/wfli/.conda/envs/pmp/lib/python3.8/runpy.py", line 265, in run_path
  File "/home/gridsan/wfli/.conda/envs/pmp/lib/python3.8/runpy.py", line 97, in _run_module_code
  File "/home/gridsan/wfli/.conda/envs/pmp/lib/python3.8/runpy.py", line 87, in _run_code
  File "test_some_gradients.py", line 1, in <module>
  File "/home/gridsan/wfli/18.369_final_project/adjoint_method/adjoint_2d.py", line 1, in <module>
  File "/home/gridsan/wfli/.conda/envs/pmp/lib/python3.8/site-packages/meep/__init__.py", line 13, in <module>
ImportError: libgfortran.so.5: cannot open shared object file: No such file or directory
Traceback (most recent call last):
  File "/home/gridsan/wfli/.conda/envs/pmp/lib/python3.8/runpy.py", line 194, in _run_module_as_main
  File "/home/gridsan/wfli/.conda/envs/pmp/lib/python3.8/runpy.py", line 87, in _run_code
  File "/home/gridsan/wfli/.conda/envs/pmp/lib/python3.8/site-packages/mpi4py/__main__.py", line 7, in <module>
  File "/home/gridsan/wfli/.conda/envs/pmp/lib/python3.8/site-packages/mpi4py/run.py", line 196, in main
  File "/home/gridsan/wfli/.conda/envs/pmp/lib/python3.8/site-packages/mpi4py/run.py", line 47, in run_command_line
  File "/home/gridsan/wfli/.conda/envs/pmp/lib/python3.8/runpy.py", line 265, in run_path
  File "/home/gridsan/wfli/.conda/envs/pmp/lib/python3.8/runpy.py", line 97, in _run_module_code
  File "/home/gridsan/wfli/.conda/envs/pmp/lib/python3.8/runpy.py", line 87, in _run_code
  File "test_some_gradients.py", line 1, in <module>
  File "/home/gridsan/wfli/18.369_final_project/adjoint_method/adjoint_2d.py", line 1, in <module>
  File "/home/gridsan/wfli/.conda/envs/pmp/lib/python3.8/site-packages/meep/__init__.py", line 13, in <module>
ImportError: libmpicxx.so.12: cannot open shared object file: No such file or directory
Traceback (most recent call last):
  File "/home/gridsan/wfli/.conda/envs/pmp/lib/python3.8/runpy.py", line 194, in _run_module_as_main
  File "/home/gridsan/wfli/.conda/envs/pmp/lib/python3.8/runpy.py", line 87, in _run_code
  File "/home/gridsan/wfli/.conda/envs/pmp/lib/python3.8/site-packages/mpi4py/__main__.py", line 7, in <module>
  File "/home/gridsan/wfli/.conda/envs/pmp/lib/python3.8/site-packages/mpi4py/run.py", line 196, in main
  File "/home/gridsan/wfli/.conda/envs/pmp/lib/python3.8/site-packages/mpi4py/run.py", line 47, in run_command_line
  File "/home/gridsan/wfli/.conda/envs/pmp/lib/python3.8/runpy.py", line 265, in run_path
  File "/home/gridsan/wfli/.conda/envs/pmp/lib/python3.8/runpy.py", line 97, in _run_module_code
  File "/home/gridsan/wfli/.conda/envs/pmp/lib/python3.8/runpy.py", line 87, in _run_code
  File "test_some_gradients.py", line 1, in <module>
  File "/home/gridsan/wfli/18.369_final_project/adjoint_method/adjoint_2d.py", line 1, in <module>
  File "/home/gridsan/wfli/.conda/envs/pmp/lib/python3.8/site-packages/meep/__init__.py", line 13, in <module>
ImportError: libmpicxx.so.12: cannot open shared object file: No such file or directory
Traceback (most recent call last):
  File "/home/gridsan/wfli/.conda/envs/pmp/lib/python3.8/runpy.py", line 194, in _run_module_as_main
  File "/home/gridsan/wfli/.conda/envs/pmp/lib/python3.8/runpy.py", line 87, in _run_code
  File "/home/gridsan/wfli/.conda/envs/pmp/lib/python3.8/site-packages/mpi4py/__main__.py", line 7, in <module>
  File "/home/gridsan/wfli/.conda/envs/pmp/lib/python3.8/site-packages/mpi4py/run.py", line 196, in main
  File "/home/gridsan/wfli/.conda/envs/pmp/lib/python3.8/site-packages/mpi4py/run.py", line 47, in run_command_line
  File "/home/gridsan/wfli/.conda/envs/pmp/lib/python3.8/runpy.py", line 265, in run_path
  File "/home/gridsan/wfli/.conda/envs/pmp/lib/python3.8/runpy.py", line 97, in _run_module_code
  File "/home/gridsan/wfli/.conda/envs/pmp/lib/python3.8/runpy.py", line 87, in _run_code
  File "test_some_gradients.py", line 1, in <module>
  File "<frozen importlib._bootstrap>", line 991, in _find_and_load
  File "<frozen importlib._bootstrap>", line 975, in _find_and_load_unlocked
  File "<frozen importlib._bootstrap>", line 671, in _load_unlocked
  File "<frozen importlib._bootstrap_external>", line 844, in exec_module
  File "<frozen importlib._bootstrap_external>", line 980, in get_code
  File "<frozen importlib._bootstrap_external>", line 1037, in get_data
BrokenPipeError: [Errno 108] Cannot send after transport endpoint shutdown: '/home/gridsan/wfli/18.369_final_project/adjoint_method/adjoint_2d.py'
Traceback (most recent call last):
  File "/home/gridsan/wfli/.conda/envs/pmp/lib/python3.8/runpy.py", line 194, in _run_module_as_main
  File "/home/gridsan/wfli/.conda/envs/pmp/lib/python3.8/runpy.py", line 87, in _run_code
  File "/home/gridsan/wfli/.conda/envs/pmp/lib/python3.8/site-packages/mpi4py/__main__.py", line 7, in <module>
  File "/home/gridsan/wfli/.conda/envs/pmp/lib/python3.8/site-packages/mpi4py/run.py", line 196, in main
  File "/home/gridsan/wfli/.conda/envs/pmp/lib/python3.8/site-packages/mpi4py/run.py", line 47, in run_command_line
  File "/home/gridsan/wfli/.conda/envs/pmp/lib/python3.8/runpy.py", line 265, in run_path
  File "/home/gridsan/wfli/.conda/envs/pmp/lib/python3.8/runpy.py", line 97, in _run_module_code
  File "/home/gridsan/wfli/.conda/envs/pmp/lib/python3.8/runpy.py", line 87, in _run_code
  File "test_some_gradients.py", line 1, in <module>
  File "<frozen importlib._bootstrap>", line 991, in _find_and_load
  File "<frozen importlib._bootstrap>", line 975, in _find_and_load_unlocked
  File "<frozen importlib._bootstrap>", line 671, in _load_unlocked
  File "<frozen importlib._bootstrap_external>", line 844, in exec_module
  File "<frozen importlib._bootstrap_external>", line 980, in get_code
  File "<frozen importlib._bootstrap_external>", line 1037, in get_data
BrokenPipeError: [Errno 108] Cannot send after transport endpoint shutdown: '/home/gridsan/wfli/18.369_final_project/adjoint_method/adjoint_2d.py'
Traceback (most recent call last):
  File "/home/gridsan/wfli/.conda/envs/pmp/lib/python3.8/runpy.py", line 194, in _run_module_as_main
  File "/home/gridsan/wfli/.conda/envs/pmp/lib/python3.8/runpy.py", line 87, in _run_code
  File "/home/gridsan/wfli/.conda/envs/pmp/lib/python3.8/site-packages/mpi4py/__main__.py", line 7, in <module>
  File "/home/gridsan/wfli/.conda/envs/pmp/lib/python3.8/site-packages/mpi4py/run.py", line 196, in main
  File "/home/gridsan/wfli/.conda/envs/pmp/lib/python3.8/site-packages/mpi4py/run.py", line 47, in run_command_line
  File "/home/gridsan/wfli/.conda/envs/pmp/lib/python3.8/runpy.py", line 265, in run_path
  File "/home/gridsan/wfli/.conda/envs/pmp/lib/python3.8/runpy.py", line 97, in _run_module_code
  File "/home/gridsan/wfli/.conda/envs/pmp/lib/python3.8/runpy.py", line 87, in _run_code
  File "test_some_gradients.py", line 1, in <module>
  File "<frozen importlib._bootstrap>", line 991, in _find_and_load
  File "<frozen importlib._bootstrap>", line 975, in _find_and_load_unlocked
  File "<frozen importlib._bootstrap>", line 671, in _load_unlocked
  File "<frozen importlib._bootstrap_external>", line 844, in exec_module
  File "<frozen importlib._bootstrap_external>", line 980, in get_code
  File "<frozen importlib._bootstrap_external>", line 1037, in get_data
BrokenPipeError: [Errno 108] Cannot send after transport endpoint shutdown: '/home/gridsan/wfli/18.369_final_project/adjoint_method/adjoint_2d.py'
Traceback (most recent call last):
  File "/home/gridsan/wfli/.conda/envs/pmp/lib/python3.8/runpy.py", line 194, in _run_module_as_main
  File "/home/gridsan/wfli/.conda/envs/pmp/lib/python3.8/runpy.py", line 87, in _run_code
  File "/home/gridsan/wfli/.conda/envs/pmp/lib/python3.8/site-packages/mpi4py/__main__.py", line 7, in <module>
  File "/home/gridsan/wfli/.conda/envs/pmp/lib/python3.8/site-packages/mpi4py/run.py", line 196, in main
  File "/home/gridsan/wfli/.conda/envs/pmp/lib/python3.8/site-packages/mpi4py/run.py", line 47, in run_command_line
  File "/home/gridsan/wfli/.conda/envs/pmp/lib/python3.8/runpy.py", line 265, in run_path
  File "/home/gridsan/wfli/.conda/envs/pmp/lib/python3.8/runpy.py", line 97, in _run_module_code
  File "/home/gridsan/wfli/.conda/envs/pmp/lib/python3.8/runpy.py", line 87, in _run_code
  File "test_some_gradients.py", line 1, in <module>
  File "<frozen importlib._bootstrap>", line 991, in _find_and_load
  File "<frozen importlib._bootstrap>", line 975, in _find_and_load_unlocked
  File "<frozen importlib._bootstrap>", line 671, in _load_unlocked
  File "<frozen importlib._bootstrap_external>", line 844, in exec_module
  File "<frozen importlib._bootstrap_external>", line 980, in get_code
  File "<frozen importlib._bootstrap_external>", line 1037, in get_data
BrokenPipeError: [Errno 108] Cannot send after transport endpoint shutdown: '/home/gridsan/wfli/18.369_final_project/adjoint_method/adjoint_2d.py'
Traceback (most recent call last):
  File "/home/gridsan/wfli/.conda/envs/pmp/lib/python3.8/runpy.py", line 194, in _run_module_as_main
  File "/home/gridsan/wfli/.conda/envs/pmp/lib/python3.8/runpy.py", line 87, in _run_code
  File "/home/gridsan/wfli/.conda/envs/pmp/lib/python3.8/site-packages/mpi4py/__main__.py", line 7, in <module>
  File "/home/gridsan/wfli/.conda/envs/pmp/lib/python3.8/site-packages/mpi4py/run.py", line 196, in main
  File "/home/gridsan/wfli/.conda/envs/pmp/lib/python3.8/site-packages/mpi4py/run.py", line 47, in run_command_line
  File "/home/gridsan/wfli/.conda/envs/pmp/lib/python3.8/runpy.py", line 265, in run_path
  File "/home/gridsan/wfli/.conda/envs/pmp/lib/python3.8/runpy.py", line 97, in _run_module_code
  File "/home/gridsan/wfli/.conda/envs/pmp/lib/python3.8/runpy.py", line 87, in _run_code
  File "test_some_gradients.py", line 1, in <module>
  File "<frozen importlib._bootstrap>", line 991, in _find_and_load
  File "<frozen importlib._bootstrap>", line 975, in _find_and_load_unlocked
  File "<frozen importlib._bootstrap>", line 671, in _load_unlocked
  File "<frozen importlib._bootstrap_external>", line 844, in exec_module
  File "<frozen importlib._bootstrap_external>", line 980, in get_code
  File "<frozen importlib._bootstrap_external>", line 1037, in get_data
BrokenPipeError: [Errno 108] Cannot send after transport endpoint shutdown: '/home/gridsan/wfli/18.369_final_project/adjoint_method/adjoint_2d.py'
Traceback (most recent call last):
  File "/home/gridsan/wfli/.conda/envs/pmp/lib/python3.8/runpy.py", line 194, in _run_module_as_main
  File "/home/gridsan/wfli/.conda/envs/pmp/lib/python3.8/runpy.py", line 87, in _run_code
  File "/home/gridsan/wfli/.conda/envs/pmp/lib/python3.8/site-packages/mpi4py/__main__.py", line 7, in <module>
  File "/home/gridsan/wfli/.conda/envs/pmp/lib/python3.8/site-packages/mpi4py/run.py", line 196, in main
  File "/home/gridsan/wfli/.conda/envs/pmp/lib/python3.8/site-packages/mpi4py/run.py", line 47, in run_command_line
  File "/home/gridsan/wfli/.conda/envs/pmp/lib/python3.8/runpy.py", line 265, in run_path
  File "/home/gridsan/wfli/.conda/envs/pmp/lib/python3.8/runpy.py", line 97, in _run_module_code
  File "/home/gridsan/wfli/.conda/envs/pmp/lib/python3.8/runpy.py", line 87, in _run_code
  File "test_some_gradients.py", line 1, in <module>
  File "<frozen importlib._bootstrap>", line 991, in _find_and_load
  File "<frozen importlib._bootstrap>", line 975, in _find_and_load_unlocked
  File "<frozen importlib._bootstrap>", line 671, in _load_unlocked
  File "<frozen importlib._bootstrap_external>", line 844, in exec_module
  File "<frozen importlib._bootstrap_external>", line 980, in get_code
  File "<frozen importlib._bootstrap_external>", line 1037, in get_data
BrokenPipeError: [Errno 108] Cannot send after transport endpoint shutdown: '/home/gridsan/wfli/18.369_final_project/adjoint_method/adjoint_2d.py'
Traceback (most recent call last):
  File "/home/gridsan/wfli/.conda/envs/pmp/lib/python3.8/runpy.py", line 194, in _run_module_as_main
  File "/home/gridsan/wfli/.conda/envs/pmp/lib/python3.8/runpy.py", line 87, in _run_code
  File "/home/gridsan/wfli/.conda/envs/pmp/lib/python3.8/site-packages/mpi4py/__main__.py", line 7, in <module>
  File "/home/gridsan/wfli/.conda/envs/pmp/lib/python3.8/site-packages/mpi4py/run.py", line 196, in main
  File "/home/gridsan/wfli/.conda/envs/pmp/lib/python3.8/site-packages/mpi4py/run.py", line 47, in run_command_line
  File "/home/gridsan/wfli/.conda/envs/pmp/lib/python3.8/runpy.py", line 265, in run_path
  File "/home/gridsan/wfli/.conda/envs/pmp/lib/python3.8/runpy.py", line 97, in _run_module_code
  File "/home/gridsan/wfli/.conda/envs/pmp/lib/python3.8/runpy.py", line 87, in _run_code
  File "test_some_gradients.py", line 1, in <module>
  File "<frozen importlib._bootstrap>", line 991, in _find_and_load
  File "<frozen importlib._bootstrap>", line 975, in _find_and_load_unlocked
  File "<frozen importlib._bootstrap>", line 671, in _load_unlocked
  File "<frozen importlib._bootstrap_external>", line 844, in exec_module
  File "<frozen importlib._bootstrap_external>", line 980, in get_code
  File "<frozen importlib._bootstrap_external>", line 1037, in get_data
BrokenPipeError: [Errno 108] Cannot send after transport endpoint shutdown: '/home/gridsan/wfli/18.369_final_project/adjoint_method/adjoint_2d.py'
Traceback (most recent call last):
  File "/home/gridsan/wfli/.conda/envs/pmp/lib/python3.8/runpy.py", line 194, in _run_module_as_main
  File "/home/gridsan/wfli/.conda/envs/pmp/lib/python3.8/runpy.py", line 87, in _run_code
  File "/home/gridsan/wfli/.conda/envs/pmp/lib/python3.8/site-packages/mpi4py/__main__.py", line 7, in <module>
  File "/home/gridsan/wfli/.conda/envs/pmp/lib/python3.8/site-packages/mpi4py/run.py", line 196, in main
  File "/home/gridsan/wfli/.conda/envs/pmp/lib/python3.8/site-packages/mpi4py/run.py", line 47, in run_command_line
  File "/home/gridsan/wfli/.conda/envs/pmp/lib/python3.8/runpy.py", line 265, in run_path
  File "/home/gridsan/wfli/.conda/envs/pmp/lib/python3.8/runpy.py", line 97, in _run_module_code
  File "/home/gridsan/wfli/.conda/envs/pmp/lib/python3.8/runpy.py", line 87, in _run_code
  File "test_some_gradients.py", line 1, in <module>
  File "/home/gridsan/wfli/18.369_final_project/adjoint_method/adjoint_2d.py", line 1, in <module>
  File "<frozen importlib._bootstrap>", line 991, in _find_and_load
  File "<frozen importlib._bootstrap>", line 971, in _find_and_load_unlocked
  File "<frozen importlib._bootstrap>", line 914, in _find_spec
  File "<frozen importlib._bootstrap_external>", line 1407, in find_spec
  File "<frozen importlib._bootstrap_external>", line 1379, in _get_spec
  File "<frozen importlib._bootstrap_external>", line 1510, in find_spec
  File "<frozen importlib._bootstrap_external>", line 1553, in _fill_cache
BrokenPipeError: [Errno 108] Cannot send after transport endpoint shutdown: '/home/gridsan/wfli/18.369_final_project/adjoint_method'
Traceback (most recent call last):
  File "/home/gridsan/wfli/.conda/envs/pmp/lib/python3.8/runpy.py", line 194, in _run_module_as_main
  File "/home/gridsan/wfli/.conda/envs/pmp/lib/python3.8/runpy.py", line 87, in _run_code
  File "/home/gridsan/wfli/.conda/envs/pmp/lib/python3.8/site-packages/mpi4py/__main__.py", line 7, in <module>
  File "/home/gridsan/wfli/.conda/envs/pmp/lib/python3.8/site-packages/mpi4py/run.py", line 196, in main
  File "/home/gridsan/wfli/.conda/envs/pmp/lib/python3.8/site-packages/mpi4py/run.py", line 47, in run_command_line
  File "/home/gridsan/wfli/.conda/envs/pmp/lib/python3.8/runpy.py", line 265, in run_path
  File "/home/gridsan/wfli/.conda/envs/pmp/lib/python3.8/runpy.py", line 97, in _run_module_code
  File "/home/gridsan/wfli/.conda/envs/pmp/lib/python3.8/runpy.py", line 87, in _run_code
  File "test_some_gradients.py", line 1, in <module>
  File "/home/gridsan/wfli/18.369_final_project/adjoint_method/adjoint_2d.py", line 1, in <module>
  File "<frozen importlib._bootstrap>", line 991, in _find_and_load
  File "<frozen importlib._bootstrap>", line 975, in _find_and_load_unlocked
  File "<frozen importlib._bootstrap>", line 671, in _load_unlocked
  File "<frozen importlib._bootstrap_external>", line 844, in exec_module
  File "<frozen importlib._bootstrap_external>", line 980, in get_code
  File "<frozen importlib._bootstrap_external>", line 1037, in get_data
BrokenPipeError: [Errno 108] Cannot send after transport endpoint shutdown: '/home/gridsan/wfli/.conda/envs/pmp/lib/python3.8/site-packages/meep/__init__.py'
Traceback (most recent call last):
  File "/home/gridsan/wfli/.conda/envs/pmp/lib/python3.8/runpy.py", line 194, in _run_module_as_main
  File "/home/gridsan/wfli/.conda/envs/pmp/lib/python3.8/runpy.py", line 87, in _run_code
  File "/home/gridsan/wfli/.conda/envs/pmp/lib/python3.8/site-packages/mpi4py/__main__.py", line 7, in <module>
  File "/home/gridsan/wfli/.conda/envs/pmp/lib/python3.8/site-packages/mpi4py/run.py", line 196, in main
  File "/home/gridsan/wfli/.conda/envs/pmp/lib/python3.8/site-packages/mpi4py/run.py", line 47, in run_command_line
  File "/home/gridsan/wfli/.conda/envs/pmp/lib/python3.8/runpy.py", line 265, in run_path
  File "/home/gridsan/wfli/.conda/envs/pmp/lib/python3.8/runpy.py", line 97, in _run_module_code
  File "/home/gridsan/wfli/.conda/envs/pmp/lib/python3.8/runpy.py", line 87, in _run_code
  File "test_some_gradients.py", line 1, in <module>
  File "<frozen importlib._bootstrap>", line 991, in _find_and_load
  File "<frozen importlib._bootstrap>", line 975, in _find_and_load_unlocked
  File "<frozen importlib._bootstrap>", line 671, in _load_unlocked
  File "<frozen importlib._bootstrap_external>", line 844, in exec_module
  File "<frozen importlib._bootstrap_external>", line 980, in get_code
  File "<frozen importlib._bootstrap_external>", line 1037, in get_data
BrokenPipeError: [Errno 108] Cannot send after transport endpoint shutdown: '/home/gridsan/wfli/18.369_final_project/adjoint_method/adjoint_2d.py'
Traceback (most recent call last):
  File "/home/gridsan/wfli/.conda/envs/pmp/lib/python3.8/runpy.py", line 194, in _run_module_as_main
  File "/home/gridsan/wfli/.conda/envs/pmp/lib/python3.8/runpy.py", line 87, in _run_code
  File "/home/gridsan/wfli/.conda/envs/pmp/lib/python3.8/site-packages/mpi4py/__main__.py", line 7, in <module>
  File "/home/gridsan/wfli/.conda/envs/pmp/lib/python3.8/site-packages/mpi4py/run.py", line 196, in main
  File "/home/gridsan/wfli/.conda/envs/pmp/lib/python3.8/site-packages/mpi4py/run.py", line 47, in run_command_line
  File "/home/gridsan/wfli/.conda/envs/pmp/lib/python3.8/runpy.py", line 265, in run_path
  File "/home/gridsan/wfli/.conda/envs/pmp/lib/python3.8/runpy.py", line 97, in _run_module_code
  File "/home/gridsan/wfli/.conda/envs/pmp/lib/python3.8/runpy.py", line 87, in _run_code
  File "test_some_gradients.py", line 1, in <module>
  File "<frozen importlib._bootstrap>", line 991, in _find_and_load
  File "<frozen importlib._bootstrap>", line 975, in _find_and_load_unlocked
  File "<frozen importlib._bootstrap>", line 671, in _load_unlocked
  File "<frozen importlib._bootstrap_external>", line 844, in exec_module
  File "<frozen importlib._bootstrap_external>", line 980, in get_code
  File "<frozen importlib._bootstrap_external>", line 1037, in get_data
BrokenPipeError: [Errno 108] Cannot send after transport endpoint shutdown: '/home/gridsan/wfli/18.369_final_project/adjoint_method/adjoint_2d.py'
Traceback (most recent call last):
  File "/home/gridsan/wfli/.conda/envs/pmp/lib/python3.8/runpy.py", line 194, in _run_module_as_main
  File "/home/gridsan/wfli/.conda/envs/pmp/lib/python3.8/runpy.py", line 87, in _run_code
  File "/home/gridsan/wfli/.conda/envs/pmp/lib/python3.8/site-packages/mpi4py/__main__.py", line 7, in <module>
  File "/home/gridsan/wfli/.conda/envs/pmp/lib/python3.8/site-packages/mpi4py/run.py", line 196, in main
  File "/home/gridsan/wfli/.conda/envs/pmp/lib/python3.8/site-packages/mpi4py/run.py", line 47, in run_command_line
  File "/home/gridsan/wfli/.conda/envs/pmp/lib/python3.8/runpy.py", line 265, in run_path
  File "/home/gridsan/wfli/.conda/envs/pmp/lib/python3.8/runpy.py", line 97, in _run_module_code
  File "/home/gridsan/wfli/.conda/envs/pmp/lib/python3.8/runpy.py", line 87, in _run_code
  File "test_some_gradients.py", line 1, in <module>
  File "<frozen importlib._bootstrap>", line 991, in _find_and_load
  File "<frozen importlib._bootstrap>", line 975, in _find_and_load_unlocked
  File "<frozen importlib._bootstrap>", line 671, in _load_unlocked
  File "<frozen importlib._bootstrap_external>", line 844, in exec_module
  File "<frozen importlib._bootstrap_external>", line 980, in get_code
  File "<frozen importlib._bootstrap_external>", line 1037, in get_data
BrokenPipeError: [Errno 108] Cannot send after transport endpoint shutdown: '/home/gridsan/wfli/18.369_final_project/adjoint_method/adjoint_2d.py'
Traceback (most recent call last):
  File "/home/gridsan/wfli/.conda/envs/pmp/lib/python3.8/runpy.py", line 194, in _run_module_as_main
  File "/home/gridsan/wfli/.conda/envs/pmp/lib/python3.8/runpy.py", line 87, in _run_code
  File "/home/gridsan/wfli/.conda/envs/pmp/lib/python3.8/site-packages/mpi4py/__main__.py", line 7, in <module>
  File "/home/gridsan/wfli/.conda/envs/pmp/lib/python3.8/site-packages/mpi4py/run.py", line 196, in main
  File "/home/gridsan/wfli/.conda/envs/pmp/lib/python3.8/site-packages/mpi4py/run.py", line 47, in run_command_line
  File "/home/gridsan/wfli/.conda/envs/pmp/lib/python3.8/runpy.py", line 265, in run_path
  File "/home/gridsan/wfli/.conda/envs/pmp/lib/python3.8/runpy.py", line 97, in _run_module_code
  File "/home/gridsan/wfli/.conda/envs/pmp/lib/python3.8/runpy.py", line 87, in _run_code
  File "test_some_gradients.py", line 1, in <module>
  File "<frozen importlib._bootstrap>", line 991, in _find_and_load
  File "<frozen importlib._bootstrap>", line 975, in _find_and_load_unlocked
  File "<frozen importlib._bootstrap>", line 671, in _load_unlocked
  File "<frozen importlib._bootstrap_external>", line 844, in exec_module
  File "<frozen importlib._bootstrap_external>", line 980, in get_code
  File "<frozen importlib._bootstrap_external>", line 1037, in get_data
BrokenPipeError: [Errno 108] Cannot send after transport endpoint shutdown: '/home/gridsan/wfli/18.369_final_project/adjoint_method/adjoint_2d.py'
Traceback (most recent call last):
  File "/home/gridsan/wfli/.conda/envs/pmp/lib/python3.8/runpy.py", line 194, in _run_module_as_main
  File "/home/gridsan/wfli/.conda/envs/pmp/lib/python3.8/runpy.py", line 87, in _run_code
  File "/home/gridsan/wfli/.conda/envs/pmp/lib/python3.8/site-packages/mpi4py/__main__.py", line 7, in <module>
  File "/home/gridsan/wfli/.conda/envs/pmp/lib/python3.8/site-packages/mpi4py/run.py", line 196, in main
  File "/home/gridsan/wfli/.conda/envs/pmp/lib/python3.8/site-packages/mpi4py/run.py", line 47, in run_command_line
  File "/home/gridsan/wfli/.conda/envs/pmp/lib/python3.8/runpy.py", line 265, in run_path
  File "/home/gridsan/wfli/.conda/envs/pmp/lib/python3.8/runpy.py", line 97, in _run_module_code
  File "/home/gridsan/wfli/.conda/envs/pmp/lib/python3.8/runpy.py", line 87, in _run_code
  File "test_some_gradients.py", line 1, in <module>
  File "<frozen importlib._bootstrap>", line 991, in _find_and_load
  File "<frozen importlib._bootstrap>", line 975, in _find_and_load_unlocked
  File "<frozen importlib._bootstrap>", line 671, in _load_unlocked
  File "<frozen importlib._bootstrap_external>", line 844, in exec_module
  File "<frozen importlib._bootstrap_external>", line 980, in get_code
  File "<frozen importlib._bootstrap_external>", line 1037, in get_data
BrokenPipeError: [Errno 108] Cannot send after transport endpoint shutdown: '/home/gridsan/wfli/18.369_final_project/adjoint_method/adjoint_2d.py'
Traceback (most recent call last):
  File "/home/gridsan/wfli/.conda/envs/pmp/lib/python3.8/runpy.py", line 194, in _run_module_as_main
  File "/home/gridsan/wfli/.conda/envs/pmp/lib/python3.8/runpy.py", line 87, in _run_code
  File "/home/gridsan/wfli/.conda/envs/pmp/lib/python3.8/site-packages/mpi4py/__main__.py", line 7, in <module>
  File "/home/gridsan/wfli/.conda/envs/pmp/lib/python3.8/site-packages/mpi4py/run.py", line 196, in main
  File "/home/gridsan/wfli/.conda/envs/pmp/lib/python3.8/site-packages/mpi4py/run.py", line 47, in run_command_line
  File "/home/gridsan/wfli/.conda/envs/pmp/lib/python3.8/runpy.py", line 265, in run_path
  File "/home/gridsan/wfli/.conda/envs/pmp/lib/python3.8/runpy.py", line 97, in _run_module_code
  File "/home/gridsan/wfli/.conda/envs/pmp/lib/python3.8/runpy.py", line 87, in _run_code
  File "test_some_gradients.py", line 1, in <module>
  File "/home/gridsan/wfli/18.369_final_project/adjoint_method/adjoint_2d.py", line 1, in <module>
  File "<frozen importlib._bootstrap>", line 991, in _find_and_load
  File "<frozen importlib._bootstrap>", line 971, in _find_and_load_unlocked
  File "<frozen importlib._bootstrap>", line 914, in _find_spec
  File "<frozen importlib._bootstrap_external>", line 1407, in find_spec
  File "<frozen importlib._bootstrap_external>", line 1379, in _get_spec
  File "<frozen importlib._bootstrap_external>", line 1510, in find_spec
  File "<frozen importlib._bootstrap_external>", line 1553, in _fill_cache
BrokenPipeError: [Errno 108] Cannot send after transport endpoint shutdown: '/home/gridsan/wfli/18.369_final_project/adjoint_method'
Traceback (most recent call last):
  File "/home/gridsan/wfli/.conda/envs/pmp/lib/python3.8/runpy.py", line 194, in _run_module_as_main
  File "/home/gridsan/wfli/.conda/envs/pmp/lib/python3.8/runpy.py", line 87, in _run_code
  File "/home/gridsan/wfli/.conda/envs/pmp/lib/python3.8/site-packages/mpi4py/__main__.py", line 7, in <module>
  File "/home/gridsan/wfli/.conda/envs/pmp/lib/python3.8/site-packages/mpi4py/run.py", line 196, in main
  File "/home/gridsan/wfli/.conda/envs/pmp/lib/python3.8/site-packages/mpi4py/run.py", line 47, in run_command_line
  File "/home/gridsan/wfli/.conda/envs/pmp/lib/python3.8/runpy.py", line 265, in run_path
  File "/home/gridsan/wfli/.conda/envs/pmp/lib/python3.8/runpy.py", line 97, in _run_module_code
  File "/home/gridsan/wfli/.conda/envs/pmp/lib/python3.8/runpy.py", line 87, in _run_code
  File "test_some_gradients.py", line 1, in <module>
  File "/home/gridsan/wfli/18.369_final_project/adjoint_method/adjoint_2d.py", line 1, in <module>
  File "<frozen importlib._bootstrap>", line 991, in _find_and_load
  File "<frozen importlib._bootstrap>", line 971, in _find_and_load_unlocked
  File "<frozen importlib._bootstrap>", line 914, in _find_spec
  File "<frozen importlib._bootstrap_external>", line 1407, in find_spec
  File "<frozen importlib._bootstrap_external>", line 1379, in _get_spec
  File "<frozen importlib._bootstrap_external>", line 1510, in find_spec
  File "<frozen importlib._bootstrap_external>", line 1553, in _fill_cache
BrokenPipeError: [Errno 108] Cannot send after transport endpoint shutdown: '/home/gridsan/wfli/18.369_final_project/adjoint_method'
Traceback (most recent call last):
  File "/home/gridsan/wfli/.conda/envs/pmp/lib/python3.8/runpy.py", line 194, in _run_module_as_main
  File "/home/gridsan/wfli/.conda/envs/pmp/lib/python3.8/runpy.py", line 87, in _run_code
  File "/home/gridsan/wfli/.conda/envs/pmp/lib/python3.8/site-packages/mpi4py/__main__.py", line 7, in <module>
  File "/home/gridsan/wfli/.conda/envs/pmp/lib/python3.8/site-packages/mpi4py/run.py", line 196, in main
  File "/home/gridsan/wfli/.conda/envs/pmp/lib/python3.8/site-packages/mpi4py/run.py", line 47, in run_command_line
  File "/home/gridsan/wfli/.conda/envs/pmp/lib/python3.8/runpy.py", line 265, in run_path
  File "/home/gridsan/wfli/.conda/envs/pmp/lib/python3.8/runpy.py", line 97, in _run_module_code
  File "/home/gridsan/wfli/.conda/envs/pmp/lib/python3.8/runpy.py", line 87, in _run_code
  File "test_some_gradients.py", line 1, in <module>
  File "<frozen importlib._bootstrap>", line 991, in _find_and_load
  File "<frozen importlib._bootstrap>", line 975, in _find_and_load_unlocked
  File "<frozen importlib._bootstrap>", line 671, in _load_unlocked
  File "<frozen importlib._bootstrap_external>", line 844, in exec_module
  File "<frozen importlib._bootstrap_external>", line 980, in get_code
  File "<frozen importlib._bootstrap_external>", line 1037, in get_data
BrokenPipeError: [Errno 108] Cannot send after transport endpoint shutdown: '/home/gridsan/wfli/18.369_final_project/adjoint_method/adjoint_2d.py'
Could not import runpy module
Could not import runpy module
Could not import runpy module
Could not import runpy module
Could not import runpy module
Could not import runpy module
Could not import runpy module
Traceback (most recent call last):
  File "/home/gridsan/wfli/.conda/envs/pmp/lib/python3.8/runpy.py", line 194, in _run_module_as_main
  File "/home/gridsan/wfli/.conda/envs/pmp/lib/python3.8/runpy.py", line 87, in _run_code
  File "/home/gridsan/wfli/.conda/envs/pmp/lib/python3.8/site-packages/mpi4py/__main__.py", line 7, in <module>
  File "/home/gridsan/wfli/.conda/envs/pmp/lib/python3.8/site-packages/mpi4py/run.py", line 196, in main
  File "/home/gridsan/wfli/.conda/envs/pmp/lib/python3.8/site-packages/mpi4py/run.py", line 47, in run_command_line
  File "/home/gridsan/wfli/.conda/envs/pmp/lib/python3.8/runpy.py", line 265, in run_path
  File "/home/gridsan/wfli/.conda/envs/pmp/lib/python3.8/runpy.py", line 97, in _run_module_code
  File "/home/gridsan/wfli/.conda/envs/pmp/lib/python3.8/runpy.py", line 87, in _run_code
  File "test_some_gradients.py", line 1, in <module>
  File "/home/gridsan/wfli/18.369_final_project/adjoint_method/adjoint_2d.py", line 1, in <module>
  File "/home/gridsan/wfli/.conda/envs/pmp/lib/python3.8/site-packages/meep/__init__.py", line 13, in <module>
ImportError: libmpi.so.12: cannot open shared object file: No such file or directory
Traceback (most recent call last):
  File "/home/gridsan/wfli/.conda/envs/pmp/lib/python3.8/runpy.py", line 194, in _run_module_as_main
  File "/home/gridsan/wfli/.conda/envs/pmp/lib/python3.8/runpy.py", line 87, in _run_code
  File "/home/gridsan/wfli/.conda/envs/pmp/lib/python3.8/site-packages/mpi4py/__main__.py", line 7, in <module>
  File "/home/gridsan/wfli/.conda/envs/pmp/lib/python3.8/site-packages/mpi4py/run.py", line 196, in main
  File "/home/gridsan/wfli/.conda/envs/pmp/lib/python3.8/site-packages/mpi4py/run.py", line 47, in run_command_line
  File "/home/gridsan/wfli/.conda/envs/pmp/lib/python3.8/runpy.py", line 265, in run_path
  File "/home/gridsan/wfli/.conda/envs/pmp/lib/python3.8/runpy.py", line 97, in _run_module_code
  File "/home/gridsan/wfli/.conda/envs/pmp/lib/python3.8/runpy.py", line 87, in _run_code
  File "test_some_gradients.py", line 1, in <module>
  File "/home/gridsan/wfli/18.369_final_project/adjoint_method/adjoint_2d.py", line 1, in <module>
  File "/home/gridsan/wfli/.conda/envs/pmp/lib/python3.8/site-packages/meep/__init__.py", line 13, in <module>
ImportError: libmpi.so.12: cannot open shared object file: No such file or directory
Traceback (most recent call last):
  File "/home/gridsan/wfli/.conda/envs/pmp/lib/python3.8/runpy.py", line 194, in _run_module_as_main
  File "/home/gridsan/wfli/.conda/envs/pmp/lib/python3.8/runpy.py", line 87, in _run_code
  File "/home/gridsan/wfli/.conda/envs/pmp/lib/python3.8/site-packages/mpi4py/__main__.py", line 7, in <module>
  File "/home/gridsan/wfli/.conda/envs/pmp/lib/python3.8/site-packages/mpi4py/run.py", line 196, in main
  File "/home/gridsan/wfli/.conda/envs/pmp/lib/python3.8/site-packages/mpi4py/run.py", line 47, in run_command_line
  File "/home/gridsan/wfli/.conda/envs/pmp/lib/python3.8/runpy.py", line 265, in run_path
  File "/home/gridsan/wfli/.conda/envs/pmp/lib/python3.8/runpy.py", line 97, in _run_module_code
  File "/home/gridsan/wfli/.conda/envs/pmp/lib/python3.8/runpy.py", line 87, in _run_code
  File "test_some_gradients.py", line 1, in <module>
  File "/home/gridsan/wfli/18.369_final_project/adjoint_method/adjoint_2d.py", line 1, in <module>
  File "/home/gridsan/wfli/.conda/envs/pmp/lib/python3.8/site-packages/meep/__init__.py", line 13, in <module>
ImportError: libmpicxx.so.12: cannot open shared object file: No such file or directory
Traceback (most recent call last):
  File "/home/gridsan/wfli/.conda/envs/pmp/lib/python3.8/runpy.py", line 194, in _run_module_as_main
  File "/home/gridsan/wfli/.conda/envs/pmp/lib/python3.8/runpy.py", line 87, in _run_code
  File "/home/gridsan/wfli/.conda/envs/pmp/lib/python3.8/site-packages/mpi4py/__main__.py", line 7, in <module>
  File "/home/gridsan/wfli/.conda/envs/pmp/lib/python3.8/site-packages/mpi4py/run.py", line 196, in main
  File "/home/gridsan/wfli/.conda/envs/pmp/lib/python3.8/site-packages/mpi4py/run.py", line 47, in run_command_line
  File "/home/gridsan/wfli/.conda/envs/pmp/lib/python3.8/runpy.py", line 265, in run_path
  File "/home/gridsan/wfli/.conda/envs/pmp/lib/python3.8/runpy.py", line 97, in _run_module_code
  File "/home/gridsan/wfli/.conda/envs/pmp/lib/python3.8/runpy.py", line 87, in _run_code
  File "test_some_gradients.py", line 1, in <module>
  File "/home/gridsan/wfli/18.369_final_project/adjoint_method/adjoint_2d.py", line 1, in <module>
  File "/home/gridsan/wfli/.conda/envs/pmp/lib/python3.8/site-packages/meep/__init__.py", line 13, in <module>
ImportError: libmpicxx.so.12: cannot open shared object file: No such file or directory
Traceback (most recent call last):
  File "/home/gridsan/wfli/.conda/envs/pmp/lib/python3.8/runpy.py", line 194, in _run_module_as_main
  File "/home/gridsan/wfli/.conda/envs/pmp/lib/python3.8/runpy.py", line 87, in _run_code
  File "/home/gridsan/wfli/.conda/envs/pmp/lib/python3.8/site-packages/mpi4py/__main__.py", line 7, in <module>
  File "/home/gridsan/wfli/.conda/envs/pmp/lib/python3.8/site-packages/mpi4py/run.py", line 196, in main
  File "/home/gridsan/wfli/.conda/envs/pmp/lib/python3.8/site-packages/mpi4py/run.py", line 47, in run_command_line
  File "/home/gridsan/wfli/.conda/envs/pmp/lib/python3.8/runpy.py", line 265, in run_path
  File "/home/gridsan/wfli/.conda/envs/pmp/lib/python3.8/runpy.py", line 97, in _run_module_code
  File "/home/gridsan/wfli/.conda/envs/pmp/lib/python3.8/runpy.py", line 87, in _run_code
  File "test_some_gradients.py", line 1, in <module>
  File "/home/gridsan/wfli/18.369_final_project/adjoint_method/adjoint_2d.py", line 1, in <module>
  File "/home/gridsan/wfli/.conda/envs/pmp/lib/python3.8/site-packages/meep/__init__.py", line 13, in <module>
ImportError: libmpi.so.12: cannot open shared object file: No such file or directory
Traceback (most recent call last):
  File "/home/gridsan/wfli/.conda/envs/pmp/lib/python3.8/runpy.py", line 194, in _run_module_as_main
  File "/home/gridsan/wfli/.conda/envs/pmp/lib/python3.8/runpy.py", line 87, in _run_code
  File "/home/gridsan/wfli/.conda/envs/pmp/lib/python3.8/site-packages/mpi4py/__main__.py", line 7, in <module>
  File "/home/gridsan/wfli/.conda/envs/pmp/lib/python3.8/site-packages/mpi4py/run.py", line 196, in main
  File "/home/gridsan/wfli/.conda/envs/pmp/lib/python3.8/site-packages/mpi4py/run.py", line 47, in run_command_line
  File "/home/gridsan/wfli/.conda/envs/pmp/lib/python3.8/runpy.py", line 265, in run_path
  File "/home/gridsan/wfli/.conda/envs/pmp/lib/python3.8/runpy.py", line 97, in _run_module_code
  File "/home/gridsan/wfli/.conda/envs/pmp/lib/python3.8/runpy.py", line 87, in _run_code
  File "test_some_gradients.py", line 1, in <module>
  File "/home/gridsan/wfli/18.369_final_project/adjoint_method/adjoint_2d.py", line 1, in <module>
  File "/home/gridsan/wfli/.conda/envs/pmp/lib/python3.8/site-packages/meep/__init__.py", line 13, in <module>
ImportError: libmpicxx.so.12: cannot open shared object file: No such file or directory
Traceback (most recent call last):
  File "/home/gridsan/wfli/.conda/envs/pmp/lib/python3.8/runpy.py", line 194, in _run_module_as_main
  File "/home/gridsan/wfli/.conda/envs/pmp/lib/python3.8/runpy.py", line 87, in _run_code
  File "/home/gridsan/wfli/.conda/envs/pmp/lib/python3.8/site-packages/mpi4py/__main__.py", line 7, in <module>
  File "/home/gridsan/wfli/.conda/envs/pmp/lib/python3.8/site-packages/mpi4py/run.py", line 196, in main
  File "/home/gridsan/wfli/.conda/envs/pmp/lib/python3.8/site-packages/mpi4py/run.py", line 47, in run_command_line
  File "/home/gridsan/wfli/.conda/envs/pmp/lib/python3.8/runpy.py", line 265, in run_path
  File "/home/gridsan/wfli/.conda/envs/pmp/lib/python3.8/runpy.py", line 97, in _run_module_code
  File "/home/gridsan/wfli/.conda/envs/pmp/lib/python3.8/runpy.py", line 87, in _run_code
  File "test_some_gradients.py", line 1, in <module>
  File "/home/gridsan/wfli/18.369_final_project/adjoint_method/adjoint_2d.py", line 1, in <module>
  File "/home/gridsan/wfli/.conda/envs/pmp/lib/python3.8/site-packages/meep/__init__.py", line 13, in <module>
ImportError: libmpicxx.so.12: cannot open shared object file: No such file or directory
Traceback (most recent call last):
  File "/home/gridsan/wfli/.conda/envs/pmp/lib/python3.8/runpy.py", line 194, in _run_module_as_main
  File "/home/gridsan/wfli/.conda/envs/pmp/lib/python3.8/runpy.py", line 87, in _run_code
  File "/home/gridsan/wfli/.conda/envs/pmp/lib/python3.8/site-packages/mpi4py/__main__.py", line 7, in <module>
  File "/home/gridsan/wfli/.conda/envs/pmp/lib/python3.8/site-packages/mpi4py/run.py", line 196, in main
  File "/home/gridsan/wfli/.conda/envs/pmp/lib/python3.8/site-packages/mpi4py/run.py", line 47, in run_command_line
  File "/home/gridsan/wfli/.conda/envs/pmp/lib/python3.8/runpy.py", line 265, in run_path
  File "/home/gridsan/wfli/.conda/envs/pmp/lib/python3.8/runpy.py", line 97, in _run_module_code
  File "/home/gridsan/wfli/.conda/envs/pmp/lib/python3.8/runpy.py", line 87, in _run_code
  File "test_some_gradients.py", line 1, in <module>
  File "/home/gridsan/wfli/18.369_final_project/adjoint_method/adjoint_2d.py", line 1, in <module>
  File "/home/gridsan/wfli/.conda/envs/pmp/lib/python3.8/site-packages/meep/__init__.py", line 13, in <module>
ImportError: libmpicxx.so.12: cannot open shared object file: No such file or directory

===================================================================================
=   BAD TERMINATION OF ONE OF YOUR APPLICATION PROCESSES
=   PID 25580 RUNNING AT d-6-3-1
=   EXIT CODE: 7
=   CLEANING UP REMAINING PROCESSES
=   YOU CAN IGNORE THE BELOW CLEANUP MESSAGES
===================================================================================
[proxy:0:0@d-6-1-3] HYD_pmcd_pmip_control_cmd_cb (pm/pmiserv/pmip_cb.c:897): assert (!closed) failed
[proxy:0:0@d-6-1-3] HYDT_dmxu_poll_wait_for_event (tools/demux/demux_poll.c:76): callback returned error status
[proxy:0:0@d-6-1-3] main (pm/pmiserv/pmip.c:169): demux engine error waiting for event
[proxy:0:3@d-6-2-2] HYD_pmcd_pmip_control_cmd_cb (pm/pmiserv/pmip_cb.c:897): assert (!closed) failed
[proxy:0:3@d-6-2-2] HYDT_dmxu_poll_wait_for_event (tools/demux/demux_poll.c:76): callback returned error status
[proxy:0:3@d-6-2-2] main (pm/pmiserv/pmip.c:169): demux engine error waiting for event
[proxy:0:7@d-6-3-2] HYD_pmcd_pmip_control_cmd_cb (pm/pmiserv/pmip_cb.c:897): assert (!closed) failed
[proxy:0:7@d-6-3-2] HYDT_dmxu_poll_wait_for_event (tools/demux/demux_poll.c:76): callback returned error status
[proxy:0:7@d-6-3-2] main (pm/pmiserv/pmip.c:169): demux engine error waiting for event
[proxy:0:9@d-6-3-4] HYD_pmcd_pmip_control_cmd_cb (pm/pmiserv/pmip_cb.c:897): assert (!closed) failed
[proxy:0:9@d-6-3-4] HYDT_dmxu_poll_wait_for_event (tools/demux/demux_poll.c:76): callback returned error status
[proxy:0:9@d-6-3-4] main (pm/pmiserv/pmip.c:169): demux engine error waiting for event
[proxy:0:5@d-6-2-4] HYD_pmcd_pmip_control_cmd_cb (pm/pmiserv/pmip_cb.c:897): assert (!closed) failed
[proxy:0:5@d-6-2-4] HYDT_dmxu_poll_wait_for_event (tools/demux/demux_poll.c:76): callback returned error status
[proxy:0:5@d-6-2-4] main (pm/pmiserv/pmip.c:169): demux engine error waiting for event
[proxy:0:11@d-6-4-2] HYD_pmcd_pmip_control_cmd_cb (pm/pmiserv/pmip_cb.c:897): assert (!closed) failed
[proxy:0:11@d-6-4-2] HYDT_dmxu_poll_wait_for_event (tools/demux/demux_poll.c:76): callback returned error status
[proxy:0:11@d-6-4-2] main (pm/pmiserv/pmip.c:169): demux engine error waiting for event
[proxy:0:8@d-6-3-3] HYD_pmcd_pmip_control_cmd_cb (pm/pmiserv/pmip_cb.c:897): assert (!closed) failed
[proxy:0:8@d-6-3-3] HYDT_dmxu_poll_wait_for_event (tools/demux/demux_poll.c:76): callback returned error status
[proxy:0:8@d-6-3-3] main (pm/pmiserv/pmip.c:169): demux engine error waiting for event
[proxy:0:13@d-6-4-4] HYD_pmcd_pmip_control_cmd_cb (pm/pmiserv/pmip_cb.c:897): assert (!closed) failed
[proxy:0:13@d-6-4-4] HYDT_dmxu_poll_wait_for_event (tools/demux/demux_poll.c:76): callback returned error status
[proxy:0:13@d-6-4-4] main (pm/pmiserv/pmip.c:169): demux engine error waiting for event
[proxy:0:14@d-6-5-1] HYD_pmcd_pmip_control_cmd_cb (pm/pmiserv/pmip_cb.c:897): assert (!closed) failed
[proxy:0:14@d-6-5-1] HYDT_dmxu_poll_wait_for_event (tools/demux/demux_poll.c:76): callback returned error status
[proxy:0:14@d-6-5-1] main (pm/pmiserv/pmip.c:169): demux engine error waiting for event
[proxy:0:12@d-6-4-3] HYD_pmcd_pmip_control_cmd_cb (pm/pmiserv/pmip_cb.c:897): assert (!closed) failed
[proxy:0:12@d-6-4-3] HYDT_dmxu_poll_wait_for_event (tools/demux/demux_poll.c:76): callback returned error status
[proxy:0:12@d-6-4-3] main (pm/pmiserv/pmip.c:169): demux engine error waiting for event
[proxy:0:4@d-6-2-3] HYD_pmcd_pmip_control_cmd_cb (pm/pmiserv/pmip_cb.c:897): assert (!closed) failed
[proxy:0:4@d-6-2-3] HYDT_dmxu_poll_wait_for_event (tools/demux/demux_poll.c:76): callback returned error status
[proxy:0:4@d-6-2-3] main (pm/pmiserv/pmip.c:169): demux engine error waiting for event
[proxy:0:1@d-6-1-4] HYD_pmcd_pmip_control_cmd_cb (pm/pmiserv/pmip_cb.c:897): assert (!closed) failed
[proxy:0:1@d-6-1-4] HYDT_dmxu_poll_wait_for_event (tools/demux/demux_poll.c:76): callback returned error status
[proxy:0:1@d-6-1-4] main (pm/pmiserv/pmip.c:169): demux engine error waiting for event
[proxy:0:10@d-6-4-1] HYD_pmcd_pmip_control_cmd_cb (pm/pmiserv/pmip_cb.c:897): assert (!closed) failed
[proxy:0:10@d-6-4-1] HYDT_dmxu_poll_wait_for_event (tools/demux/demux_poll.c:76): callback returned error status
[proxy:0:10@d-6-4-1] main (pm/pmiserv/pmip.c:169): demux engine error waiting for event
srun: error: d-6-2-3: task 4: Exited with exit code 7
srun: error: d-6-1-3: task 0: Exited with exit code 7
srun: error: d-6-2-4: task 5: Exited with exit code 7
srun: error: d-6-3-4: task 9: Exited with exit code 7
srun: error: d-6-4-2: task 11: Exited with exit code 7
srun: error: d-6-4-4: task 13: Exited with exit code 7
srun: error: d-6-3-3: task 8: Exited with exit code 7
srun: error: d-6-2-2: task 3: Exited with exit code 7
srun: error: d-6-1-4: task 1: Exited with exit code 7
srun: error: d-6-4-1: task 10: Exited with exit code 7
srun: error: d-6-3-2: task 7: Exited with exit code 7
srun: error: d-6-5-1: task 14: Exited with exit code 7
srun: error: d-6-4-3: task 12: Exited with exit code 7
YOUR APPLICATION TERMINATED WITH THE EXIT STRING: Bus error (signal 7)
This typically refers to a problem with your application.
Please see the FAQ page for debugging suggestions
